<mujoco model="triton_lidar">
  <!-- compiler eulerseq="XYZ"/-->
  <compiler angle="degree" coordinate="local" eulerseq="XYZ"/>
  <default>
    <default class="unused"/>
    <joint armature="1" damping="1" limited="false"/>
  </default>
  <asset>
    <texture name="grid" type="2d" builtin="checker" rgb1="0.10000000000000001 0.20000000000000001 0.29999999999999999" rgb2="0.20000000000000001 0.29999999999999999 0.40000000000000002" width="512" height="512"/>
    <material name="grid" class="unused" texture="grid" texrepeat="1 1" texuniform="true" reflectance="0.20000000000000001"/>
    <mesh name="triton" class="unused" file="triton.stl" scale="1 1 1"/>
    <material name="material_1" class="unused" emission="0" specular="0.0099999997764825821" rgba="0.95999997854232788 0.95999997854232788 0.95999997854232788 1"/>
    <material name="material_2" class="unused" emission="0" specular="0.0099999997764825821" rgba="0.68000000715255737 0.68000000715255737 0.68000000715255737 1"/>
    <material name="material_3" class="unused" emission="0" specular="0.0099999997764825821" rgba="0.68000000715255737 0.68000000715255737 0.68000000715255737 1"/>
    <material name="material_4" class="unused" emission="0" specular="0.0099999997764825821" rgba="0.68000000715255737 0.68000000715255737 0.68000000715255737 1"/>
    <material name="material_5" class="unused" emission="0" specular="0.0099999997764825821" rgba="0.68000000715255737 0.68000000715255737 0.68000000715255737 1"/>
  </asset>
  <worldbody>
    <light name="light_1" directional="true" diffuse=".8 .8 .8" specular=".1 .1 .1" pos="0 0 1" dir="0 0 -1"/>
    <geom name="floor" class="unused" type="plane" condim="3" size="0 0 0.050000000000000003" material="grid" pos="0 0 -1"/>

    <body name="triton" pos="0 0 0.035000000000000003" euler="0 -0 0">

      <inertial pos="0 0 0" mass="1" fullinertia="0.14583299999999999 0.14583299999999999 0.125 0 0 0"/>
      <geom name="visual" class="unused" type="mesh" contype="0" conaffinity="0" group="1" material="material_1" pos="0 0 0" euler="0 -0 -30" mesh="triton"/>
      <geom name="collision" class="unused" type="cylinder" size="0.10 0.002" group="2" friction="1 0.0050000000000000001 0.0001" pos="0 0 0.035" euler="0 -0 0"/>

      <joint name="trition_body" armature="1" damping="1" type="free"/>

      <body name="lidar" pos="0 0 -0.035000000000000003" euler="0 -0 0">
        <inertial pos="0 0 0.161" mass="0.125" fullinertia="0.001 0.001 0.001 0 0 0"/>
        <geom name="lidar_sensor_collision" class="unused" type="cylinder" group="2" size="0.0508 0.0208" friction="1 0.0050000000000000001 0.0001" pos="0 0 0.161" euler="0 -0 0"/>
        <!--geom name="lidar_sensor_visual" class="unused" type="cylinder" contype="0" conaffinity="0" group="0" size="0.0508 0.0000000001" material="material_2" pos="0 0 0.161" euler="0 -0 0"/>-->
        <site name="hls_lfcd_lds" class="unused" pos="0 0 0.17100000000000001" euler="0 -0 0"/>
      </body>

      <body name="right_wheel_link" pos="-0.11 0 0.03" euler="0.0045263665815347721 89.95437383555452 0.0041825919044565273">
        <inertial pos="0 0 0" mass="1" fullinertia="0.14583299999999999 0.14583299999999999 0.125 0 0 0"/>
        <geom name="collision_0" class="unused" type="cylinder"  size="0.029999999999999999 0.0074999999999999997" friction="1 0.0050000000000000001 0.0001" />
        <!--This is one of the wheels-->
        <!-- geom name="visual_0" class="unused" type="cylinder" contype="0" conaffinity="0" group="0" size="0.029999999999999999 0.0074999999999999997" material="material_3" pos="-1.0408340855860843e-17 0 -1.3877787807814457e-17" euler="6.2957858083358728e-37 -2.9731007884611702e-15 -2.4265706493099341e-20"/-->
        <joint name="right_wheel" class="unused" type="hinge" pos="-1.0408340855860843e-17 0 -1.3877787807814457e-17" axis="0 0 1"/>
      </body>

      <body name="back_wheel_link" pos="0.055 0.095000000000000001 0.03" euler="119.99913469661091 89.954373835546534 0.00017188733800956195">
        <inertial pos="0 0 0" mass="1" fullinertia="0.14583299999999999 0.14583299999999999 0.125 0 0 0"/>
        <geom name="collision_1" class="unused" type="cylinder"  size="0.029999999999999999 0.0074999999999999997" friction="1 0.0050000000000000001 0.0001" />
        <!-- geom name="visual_0_0" class="unused" type="cylinder" contype="0" conaffinity="0" group="0" size="0.029999999999999999 0.0074999999999999997" material="material_4" pos="0 -1.7347234759768071e-17 1.3877787807814457e-17" euler="0 -0 0"/-->
        <joint name="back_wheel" class="unused" type="hinge" pos="0 -1.7347234759768071e-17 1.3877787807814457e-17" axis="0 0 1"/>
      </body>

      <body name="left_wheel_link" pos="0.055 -0.095000000000000001 0.03" euler="-119.9928321608599 89.954373835546534 0.0052712117170394205">
        <inertial pos="0 0 0" mass="1" fullinertia="0.14583299999999999 0.14583299999999999 0.125 0 0 0"/>
        <geom name="collision_2" class="unused" type="cylinder"  size="0.029999999999999999 0.0074999999999999997" friction="1 0.0050000000000000001 0.0001" />
        <!-- geom name="visual_0_1" class="unused" type="cylinder" contype="0" conaffinity="0" group="0" size="0.029999999999999999 0.0074999999999999997" material="material_5" pos="6.9388939039072284e-18 -3.1225022567582528e-17 -1.3877787807814457e-17" euler="0 -0 0"/-->
        <joint name="left_wheel" class="unused"  type="hinge" pos="6.9388939039072284e-18 -3.1225022567582528e-17 -1.3877787807814457e-17" axis="0 0 1"/>
      </body>
    </body>
  </worldbody>

  <tendon>
    <fixed name = "go_foward">
      <joint joint = "right_wheel" coef = "1"/>
      <joint joint = "left_wheel" coef = "-1"/>
    </fixed>

    <fixed name = "turn">
      <joint joint = "right_wheel" coef = "1"/>
      <joint joint = "left_wheel" coef = "1"/>
      <joint joint = "back_wheel" coef = "1"/>
    </fixed>


  </tendon>

  <actuator>
    <motor name="right_wheel" gear="3" joint="right_wheel"/>
    <motor name="back_wheel" gear="3" joint="back_wheel"/>
    <motor name="left_wheel" gear="3" joint="left_wheel"/>

    <motor name="go_forward" tendon="go_foward" gear="5"/>
    <motor name="turn" tendon="turn" gear="3"/>
    
  </actuator>  
</mujoco>
